Traceback (most recent call last):
  File "/home/arthur/miniconda3/envs/av-blog/lib/python3.11/site-packages/jupyter_cache/executors/utils.py", line 58, in single_nb_execution
    executenb(
  File "/home/arthur/miniconda3/envs/av-blog/lib/python3.11/site-packages/nbclient/client.py", line 1314, in execute
    return NotebookClient(nb=nb, resources=resources, km=km, **kwargs).execute()
           ^^^^^^^^^^^^^^^^^^^^^^^^^^^^^^^^^^^^^^^^^^^^^^^^^^^^^^^^^^^^^^^^^^^^^
  File "/home/arthur/miniconda3/envs/av-blog/lib/python3.11/site-packages/jupyter_core/utils/__init__.py", line 165, in wrapped
    return loop.run_until_complete(inner)
           ^^^^^^^^^^^^^^^^^^^^^^^^^^^^^^
  File "/home/arthur/miniconda3/envs/av-blog/lib/python3.11/asyncio/base_events.py", line 654, in run_until_complete
    return future.result()
           ^^^^^^^^^^^^^^^
  File "/home/arthur/miniconda3/envs/av-blog/lib/python3.11/site-packages/nbclient/client.py", line 709, in async_execute
    await self.async_execute_cell(
  File "/home/arthur/miniconda3/envs/av-blog/lib/python3.11/site-packages/nbclient/client.py", line 1062, in async_execute_cell
    await self._check_raise_for_error(cell, cell_index, exec_reply)
  File "/home/arthur/miniconda3/envs/av-blog/lib/python3.11/site-packages/nbclient/client.py", line 918, in _check_raise_for_error
    raise CellExecutionError.from_cell_and_msg(cell, exec_reply_content)
nbclient.exceptions.CellExecutionError: An error occurred while executing the following cell:
------------------
plt.plot(beta_hat)
plt.plot(beta)
plt.plot(res.x)
------------------


[0;31m---------------------------------------------------------------------------[0m
[0;31mNameError[0m                                 Traceback (most recent call last)
Cell [0;32mIn[7], line 3[0m
[1;32m      1[0m plt[38;5;241m.[39mplot(beta_hat)
[1;32m      2[0m plt[38;5;241m.[39mplot(beta)
[0;32m----> 3[0m plt[38;5;241m.[39mplot([43mres[49m[38;5;241m.[39mx)

[0;31mNameError[0m: name 'res' is not defined

